Workbook

Sheet Útmutató
A1: ICP ügyfélminősítő – útmutató
A3: Mire jó?
A4: Az ügyfeleket 33 szempont alapján 0–100 pontra értékeli, rangsorolja, öt státuszba sorolja, és ebből díjat, illetve jutalékos modellt javasol.
A6: Kiket tekintünk ideális ügyfélnek?
A7: Felelősségteljes, fenntartható, zöld szemléletű cégeket, amelyek elsősorban szükségleteket elégítenek ki, nem igényeket:
A8: • Emberközpontú szolgáltatók (egészség, oktatás, mentális jóllét, fejlesztés)
A9: • Tudatos termelők és alkotók (fenntartható termékek, kézműves márkák, gazdaságok)
A10: • Hatásközpontú szervezetek (közösségi, környezeti és társadalmi projektek)
A11: Kizáró feltétel: „Értékalapú szegmens” legfeljebb 1 pont; „Felelősség, fenntarthatóság” legfeljebb 3 pont (a szegmensnél ez az „Értékeinkkel nem összeegyeztethető” érték). Az ilyen ügyfél automatikusan 5. státuszú, és elutasítjuk. Hiányzó adat nem zár ki.
A13: Státuszok
A14: 1. Stabil rendszer (rendszerpontszám ≥ 70; szorzó 0,90, jutalék 5%): A kampányok és a kapcsolódó marketingelemek jól működnek, az eredmények kiszámíthatók. A feladat elsősorban az ellenőrzés, fenntartás és kisebb finomhangolás.
A15: 2. Menedzselt rendszer (rendszerpontszám ≥ 55; szorzó 1,00, jutalék 3%): A rendszer működik, de rendszeres operatív kezelést igényel: ismétlődő kampányfrissítések, szezonális promóciók, kreatívcserék, tervezhető optimalizálási feladatok.
... A43: A fájl feltölthető Google Drive-ra és megnyitható Google Táblázatként; a képletek ott is működnek.

Sheet Ügyfelek
A1: Ügyfél neve | B1: Értékalapú szegmens | C1: Felelősség, fenntarthatóság (1–10) | D1: Sürgősség (1–10) | E1: A piac mérete (1–10) | F1: Árazási potenciál (1–10) | G1: Vásárlószerzés költsége (1–10) | H1: Leszállítás költsége (1–10) | I1: Egyediség, egyedi tulajdonság (1–10) | J1: A piac gyorsasága (1–10) | K1: Befektetési igény (1–10) | L1: Upsell-potenciál (1–10) | M1: Örökzöld potenciál (1–10) | N1: Látványos demonstrálhatóság (1–10) | O1: Dizájn, vonzó megjelenés (1–10) | P1: Egyszerű használat (1–10) | Q1: Problémát old meg (1–10) | R1: Újdonság (1–10) | S1: Iparági illeszkedés (1–10) | T1: Éves árbevétel (M Ft) | U1: Havi hirdetési keret (Ft) | V1: Marketing-érettség (1–10) | W1: Jelenlegi ROAS | X1: Növekedési potenciál (1–10) | Y1: Nyitottság a jutalékos modellre | Z1: Átlagos fizetési késés (nap) | AA1: Együttműködés hossza (hónap) | AB1: Döntéshozó, együttműködés (1–10) | AC1: Kezelhetőség (1–10) | AD1: Ajánlási, referenciaérték (1–10) | AE1: Reális elvárások (1–10) | AF1: Emberi oldal (1–10) | AG1: Szakmai színvonal (1–10) | AH1: Korábbi ügynökségi tapasztalat | AI1: Google Ads (igen/nem) | AJ1: Meta (igen/nem) | AK1: Egyéb csatornák száma | AL1: Becsült havi munkaóra | AM1: Jelenlegi havi díj (Ft) | AN1: Havi mért bevétel (Ft) | AO1: Megjegyzés

Sheet Rangsor
A1: ICP-rangsor – pontszám szerint csökkenő sorrendben
A2: Automatikusan frissül az Ügyfelek lap alapján. A csoportoszlopok 0–100 között mutatják, hol erős az ügyfél. Holtversenynél a korábban felvett ügyfél áll elöl.
A4: Rang | B4: Ügyfél | C4: ICP pontszám | D4: Rendszerpontszám | E4: Státusz | F4: Státusz megnevezése | G4: Döntés | H4: Értékek | I4: Marketingezhetőség | J4: Üzleti illeszkedés | K4: Kapcsolat | L4: Javasolt fix havi díj | M4: Jelenlegi díj | N4: Eltérés (Ft) | O4: Eltérés (%) | P4: Jutalékos modell | Q4: Jutalékos: fix díj | R4: Jutalékos: jutalék % | S4: Díjmodell | T4: Leggyengébb terület | U4: Hiányzó adatok | W4: sor
A5: =IF($W5="","",INDEX('Eredmény'!$AO$2:$AO$201,$W5)) | B5: =IF($W5="","",INDEX('Eredmény'!$A$2:$A$201,$W5)) | C5: =IF($W5="","",INDEX('Eredmény'!$AM$2:$AM$201,$W5)) | D5: =IF($W5="","",INDEX('Eredmény'!$AN$2:$AN$201,$W5)) | E5: =IF($W5="","",INDEX('Eredmény'!$AQ$2:$AQ$201,$W5)) | F5: =IF($W5="","",INDEX('Eredmény'!$AR$2:$AR$201,$W5)) | G5: =IF($W5="","",INDEX('Eredmény'!$AS$2:$AS$201,$W5)) | H5: =IF($W5="","",INDEX('Eredmény'!$AI$2:$AI$201,$W5)) | I5: =IF($W5="","",INDEX('Eredmény'!$AJ$2:$AJ$201,$W5)) | J5: =IF($W5="","",INDEX('Eredmény'!$AK$2:$AK$201,$W5)) | K5: =IF($W5="","",INDEX('Eredmény'!$AL$2:$AL$201,$W5)) | L5: =IF($W5="","",INDEX('Eredmény'!$AZ$2:$AZ$201,$W5)) | M5: =IF($W5="","",INDEX('Eredmény'!$BB$2:$BB$201,$W5)) | N5: =IF($W5="","",INDEX('Eredmény'!$BC$2:$BC$201,$W5)) | O5: =IF($W5="","",INDEX('Eredmény'!$BD$2:$BD$201,$W5)) | P5: =IF($W5="","",INDEX('Eredmény'!$BE$2:$BE$201,$W5)) | Q5: =IF($W5="","",INDEX('Eredmény'!$BF$2:$BF$201,$W5)) | R5: =IF($W5="","",INDEX('Eredmény'!$BG$2:$BG$201,$W5)) | S5: =IF($W5="","",INDEX('Eredmény'!$AT$2:$AT$201,$W5)) | T5: =IF($W5="","",INDEX('Eredmény'!$AV$2:$AV$201,$W5)) | U5: =IF($W5="","",INDEX('Eredmény'!$BI$2:$BI$201,$W5)) | W5: =IFERROR(MATCH(LARGE('Eredmény'!$DY$2:$DY$201,1),'Eredmény'!$DY$2:$DY$201,0),"")
A6: =IF($W6="","",INDEX('Eredmény'!$AO$2:$AO$201,$W6)) | B6: =IF($W6="","",INDEX('Eredmény'!$A$2:$A$201,$W6)) | C6: =IF($W6="","",INDEX('Eredmény'!$AM$2:$AM$201,$W6)) | D6: =IF($W6="","",INDEX('Eredmény'!$AN$2:$AN$201,$W6)) | E6: =IF($W6="","",INDEX('Eredmény'!$AQ$2:$AQ$201,$W6)) | F6: =IF($W6="","",INDEX('Eredmény'!$AR$2:$AR$201,$W6)) | G6: =IF($W6="","",INDEX('Eredmény'!$AS$2:$AS$201,$W6)) | H6: =IF($W6="","",INDEX('Eredmény'!$AI$2:$AI$201,$W6)) | I6: =IF($W6="","",INDEX('Eredmény'!$AJ$2:$AJ$201,$W6)) | J6: =IF($W6="","",INDEX('Eredmény'!$AK$2:$AK$201,$W6)) | K6: =IF($W6="","",INDEX('Eredmény'!$AL$2:$AL$201,$W6)) | L6: =IF($W6="","",INDEX('Eredmény'!$AZ$2:$AZ$201,$W6)) | M6: =IF($W6="","",INDEX('Eredmény'!$BB$2:$BB$201,$W6)) | N6: =IF($W6="","",INDEX('Eredmény'!$BC$2:$BC$201,$W6)) | O6: =IF($W6="","",INDEX('Eredmény'!$BD$2:$BD$201,$W6)) | P6: =IF($W6="","",INDEX('Eredmény'!$BE$2:$BE$201,$W6)) | Q6: =IF($W6="","",INDEX('Eredmény'!$BF$2:$BF$201,$W6)) | R6: =IF($W6="","",INDEX('Eredmény'!$BG$2:$BG$201,$W6)) | S6: =IF($W6="","",INDEX('Eredmény'!$AT$2:$AT$201,$W6)) | T6: =IF($W6="","",INDEX('Eredmény'!$AV$2:$AV$201,$W6)) | U6: =IF($W6="","",INDEX('Eredmény'!$BI$2:$BI$201,$W6)) | W6: =IFERROR(MATCH(LARGE('Eredmény'!$DY$2:$DY$201,2),'Eredmény'!$DY$2:$DY$201,0),"")
A7: =IF($W7="","",INDEX('Eredmény'!$AO$2:$AO$201,$W7)) | B7: =IF($W7="","",INDEX('Eredmény'!$A$2:$A$201,$W7)) | C7: =IF($W7="","",INDEX('Eredmény'!$AM$2:$AM$201,$W7)) | D7: =IF($W7="","",INDEX('Eredmény'!$AN$2:$AN$201,$W7)) | E7: =IF($W7="","",INDEX('Eredmény'!$AQ$2:$AQ$201,$W7)) | F7: =IF($W7="","",INDEX('Eredmény'!$AR$2:$AR$201,$W7)) | G7: =IF($W7="","",INDEX('Eredmény'!$AS$2:$AS$201,$W7)) | H7: =IF($W7="","",INDEX('Eredmény'!$AI$2:$AI$201,$W7)) | I7: =IF($W7="","",INDEX('Eredmény'!$AJ$2:$AJ$201,$W7)) | J7: =IF($W7="","",INDEX('Eredmény'!$AK$2:$AK$201,$W7)) | K7: =IF($W7="","",INDEX('Eredmény'!$AL$2:$AL$201,$W7)) | L7: =IF($W7="","",INDEX('Eredmény'!$AZ$2:$AZ$201,$W7)) | M7: =IF($W7="","",INDEX('Eredmény'!$BB$2:$BB$201,$W7)) | N7: =IF($W7="","",INDEX('Eredmény'!$BC$2:$BC$201,$W7)) | O7: =IF($W7="","",INDEX('Eredmény'!$BD$2:$BD$201,$W7)) | P7: =IF($W7="","",INDEX('Eredmény'!$BE$2:$BE$201,$W7)) | Q7: =IF($W7="","",INDEX('Eredmény'!$BF$2:$BF$201,$W7)) | R7: =IF($W7="","",INDEX('Eredmény'!$BG$2:$BG$201,$W7)) | S7: =IF($W7="","",INDEX('Eredmény'!$AT$2:$AT$201,$W7)) | T7: =IF($W7="","",INDEX('Eredmény'!$AV$2:$AV$201,$W7)) | U7: =IF($W7="","",INDEX('Eredmény'!$BI$2:$BI$201,$W7)) | W7: =IFERROR(MATCH(LARGE('Eredmény'!$DY$2:$DY$201,3),'Eredmény'!$DY$2:$DY$201,0),"")
A8: =IF($W8="","",INDEX('Eredmény'!$AO$2:$AO$201,$W8)) | B8: =IF($W8="","",INDEX('Eredmény'!$A$2:$A$201,$W8)) | C8: =IF($W8="","",INDEX('Eredmény'!$AM$2:$AM$201,$W8)) | D8: =IF($W8="","",INDEX('Eredmény'!$AN$2:$AN$201,$W8)) | E8: =IF($W8="","",INDEX('Eredmény'!$AQ$2:$AQ$201,$W8)) | F8: =IF($W8="","",INDEX('Eredmény'!$AR$2:$AR$201,$W8)) | G8: =IF($W8="","",INDEX('Eredmény'!$AS$2:$AS$201,$W8)) | H8: =IF($W8="","",INDEX('Eredmény'!$AI$2:$AI$201,$W8)) | I8: =IF($W8="","",INDEX('Eredmény'!$AJ$2:$AJ$201,$W8)) | J8: =IF($W8="","",INDEX('Eredmény'!$AK$2:$AK$201,$W8)) | K8: =IF($W8="","",INDEX('Eredmény'!$AL$2:$AL$201,$W8)) | L8: =IF($W8="","",INDEX('Eredmény'!$AZ$2:$AZ$201,$W8)) | M8: =IF($W8="","",INDEX('Eredmény'!$BB$2:$BB$201,$W8)) | N8: =IF($W8="","",INDEX('Eredmény'!$BC$2:$BC$201,$W8)) | O8: =IF($W8="","",INDEX('Eredmény'!$BD$2:$BD$201,$W8)) | P8: =IF($W8="","",INDEX('Eredmény'!$BE$2:$BE$201,$W8)) | Q8: =IF($W8="","",INDEX('Eredmény'!$BF$2:$BF$201,$W8)) | R8: =IF($W8="","",INDEX('Eredmény'!$BG$2:$BG$201,$W8)) | S8: =IF($W8="","",INDEX('Eredmény'!$AT$2:$AT$201,$W8)) | T8: =IF($W8="","",INDEX('Eredmény'!$AV$2:$AV$201,$W8)) | U8: =IF($W8="","",INDEX('Eredmény'!$BI$2:$BI$201,$W8)) | W8: =IFERROR(MATCH(LARGE('Eredmény'!$DY$2:$DY$201,4),'Eredmény'!$DY$2:$DY$201,0),"")
A9: =IF($W9="","",INDEX('Eredmény'!$AO$2:$AO$201,$W9)) | B9: =IF($W9="","",INDEX('Eredmény'!$A$2:$A$201,$W9)) | C9: =IF($W9="","",INDEX('Eredmény'!$AM$2:$AM$201,$W9)) | D9: =IF($W9="","",INDEX('Eredmény'!$AN$2:$AN$201,$W9)) | E9: =IF($W9="","",INDEX('Eredmény'!$AQ$2:$AQ$201,$W9)) | F9: =IF($W9="","",INDEX('Eredmény'!$AR$2:$AR$201,$W9)) | G9: =IF($W9="","",INDEX('Eredmény'!$AS$2:$AS$201,$W9)) | H9: =IF($W9="","",INDEX('Eredmény'!$AI$2:$AI$201,$W9)) | I9: =IF($W9="","",INDEX('Eredmény'!$AJ$2:$AJ$201,$W9)) | J9: =IF($W9="","",INDEX('Eredmény'!$AK$2:$AK$201,$W9)) | K9: =IF($W9="","",INDEX('Eredmény'!$AL$2:$AL$201,$W9)) | L9: =IF($W9="","",INDEX('Eredmény'!$AZ$2:$AZ$201,$W9)) | M9: =IF($W9="","",INDEX('Eredmény'!$BB$2:$BB$201,$W9)) | N9: =IF($W9="","",INDEX('Eredmény'!$BC$2:$BC$201,$W9)) | O9: =IF($W9="","",INDEX('Eredmény'!$BD$2:$BD$201,$W9)) | P9: =IF($W9="","",INDEX('Eredmény'!$BE$2:$BE$201,$W9)) | Q9: =IF($W9="","",INDEX('Eredmény'!$BF$2:$BF$201,$W9)) | R9: =IF($W9="","",INDEX('Eredmény'!$BG$2:$BG$201,$W9)) | S9: =IF($W9="","",INDEX('Eredmény'!$AT$2:$AT$201,$W9)) | T9: =IF($W9="","",INDEX('Eredmény'!$AV$2:$AV$201,$W9)) | U9: =IF($W9="","",INDEX('Eredmény'!$BI$2:$BI$201,$W9)) | W9: =IFERROR(MATCH(LARGE('Eredmény'!$DY$2:$DY$201,5),'Eredmény'!$DY$2:$DY$201,0),"")
A10: =IF($W10="","",INDEX('Eredmény'!$AO$2:$AO$201,$W10)) | B10: =IF($W10="","",INDEX('Eredmény'!$A$2:$A$201,$W10)) | C10: =IF($W10="","",INDEX('Eredmény'!$AM$2:$AM$201,$W10)) | D10: =IF($W10="","",INDEX('Eredmény'!$AN$2:$AN$201,$W10)) | E10: =IF($W10="","",INDEX('Eredmény'!$AQ$2:$AQ$201,$W10)) | F10: =IF($W10="","",INDEX('Eredmény'!$AR$2:$AR$201,$W10)) | G10: =IF($W10="","",INDEX('Eredmény'!$AS$2:$AS$201,$W10)) | H10: =IF($W10="","",INDEX('Eredmény'!$AI$2:$AI$201,$W10)) | I10: =IF($W10="","",INDEX('Eredmény'!$AJ$2:$AJ$201,$W10)) | J10: =IF($W10="","",INDEX('Eredmény'!$AK$2:$AK$201,$W10)) | K10: =IF($W10="","",INDEX('Eredmény'!$AL$2:$AL$201,$W10)) | L10: =IF($W10="","",INDEX('Eredmény'!$AZ$2:$AZ$201,$W10)) | M10: =IF($W10="","",INDEX('Eredmény'!$BB$2:$BB$201,$W10)) | N10: =IF($W10="","",INDEX('Eredmény'!$BC$2:$BC$201,$W10)) | O10: =IF($W10="","",INDEX('Eredmény'!$BD$2:$BD$201,$W10)) | P10: =IF($W10="","",INDEX('Eredmény'!$BE$2:$BE$201,$W10)) | Q10: =IF($W10="","",INDEX('Eredmény'!$BF$2:$BF$201,$W10)) | R10: =IF($W10="","",INDEX('Eredmény'!$BG$2:$BG$201,$W10)) | S10: =IF($W10="","",INDEX('Eredmény'!$AT$2:$AT$201,$W10)) | T10: =IF($W10="","",INDEX('Eredmény'!$AV$2:$AV$201,$W10)) | U10: =IF($W10="","",INDEX('Eredmény'!$BI$2:$BI$201,$W10)) | W10: =IFERROR(MATCH(LARGE('Eredmény'!$DY$2:$DY$201,6),'Eredmény'!$DY$2:$DY$201,0),"")
A11: =IF($W11="","",INDEX('Eredmény'!$AO$2:$AO$201,$W11)) | B11: =IF($W11="","",INDEX('Eredmény'!$A$2:$A$201,$W11)) | C11: =IF($W11="","",INDEX('Eredmény'!$AM$2:$AM$201,$W11)) | D11: =IF($W11="","",INDEX('Eredmény'!$AN$2:$AN$201,$W11)) | E11: =IF($W11="","",INDEX('Eredmény'!$AQ$2:$AQ$201,$W11)) | F11: =IF($W11="","",INDEX('Eredmény'!$AR$2:$AR$201,$W11)) | G11: =IF($W11="","",INDEX('Eredmény'!$AS$2:$AS$201,$W11)) | H11: =IF($W11="","",INDEX('Eredmény'!$AI$2:$AI$201,$W11)) | I11: =IF($W11="","",INDEX('Eredmény'!$AJ$2:$AJ$201,$W11)) | J11: =IF($W11="","",INDEX('Eredmény'!$AK$2:$AK$201,$W11)) | K11: =IF($W11="","",INDEX('Eredmény'!$AL$2:$AL$201,$W11)) | L11: =IF($W11="","",INDEX('Eredmény'!$AZ$2:$AZ$201,$W11)) | M11: =IF($W11="","",INDEX('Eredmény'!$BB$2:$BB$201,$W11)) | N11: =IF($W11="","",INDEX('Eredmény'!$BC$2:$BC$201,$W11)) | O11: =IF($W11="","",INDEX('Eredmény'!$BD$2:$BD$201,$W11)) | P11: =IF($W11="","",INDEX('Eredmény'!$BE$2:$BE$201,$W11)) | Q11: =IF($W11="","",INDEX('Eredmény'!$BF$2:$BF$201,$W11)) | R11: =IF($W11="","",INDEX('Eredmény'!$BG$2:$BG$201,$W11)) | S11: =IF($W11="","",INDEX('Eredmény'!$AT$2:$AT$201,$W11)) | T11: =IF($W11="","",INDEX('Eredmény'!$AV$2:$AV$201,$W11)) | U11: =IF($W11="","",INDEX('Eredmény'!$BI$2:$BI$201,$W11)) | W11: =IFERROR(MATCH(LARGE('Eredmény'!$DY$2:$DY$201,7),'Eredmény'!$DY$2:$DY$201,0),"")
A12: =IF($W12="","",INDEX('Eredmény'!$AO$2:$AO$201,$W12)) | B12: =IF($W12="","",INDEX('Eredmény'!$A$2:$A$201,$W12)) | C12: =IF($W12="","",INDEX('Eredmény'!$AM$2:$AM$201,$W12)) | D12: =IF($W12="","",INDEX('Eredmény'!$AN$2:$AN$201,$W12)) | E12: =IF($W12="","",INDEX('Eredmény'!$AQ$2:$AQ$201,$W12)) | F12: =IF($W12="","",INDEX('Eredmény'!$AR$2:$AR$201,$W12)) | G12: =IF($W12="","",INDEX('Eredmény'!$AS$2:$AS$201,$W12)) | H12: =IF($W12="","",INDEX('Eredmény'!$AI$2:$AI$201,$W12)) | I12: =IF($W12="","",INDEX('Eredmény'!$AJ$2:$AJ$201,$W12)) | J12: =IF($W12="","",INDEX('Eredmény'!$AK$2:$AK$201,$W12)) | K12: =IF($W12="","",INDEX('Eredmény'!$AL$2:$AL$201,$W12)) | L12: =IF($W12="","",INDEX('Eredmény'!$AZ$2:$AZ$201,$W12)) | M12: =IF($W12="","",INDEX('Eredmény'!$BB$2:$BB$201,$W12)) | N12: =IF($W12="","",INDEX('Eredmény'!$BC$2:$BC$201,$W12)) | O12: =IF($W12="","",INDEX('Eredmény'!$BD$2:$BD$201,$W12)) | P12: =IF($W12="","",INDEX('Eredmény'!$BE$2:$BE$201,$W12)) | Q12: =IF($W12="","",INDEX('Eredmény'!$BF$2:$BF$201,$W12)) | R12: =IF($W12="","",INDEX('Eredmény'!$BG$2:$BG$201,$W12)) | S12: =IF($W12="","",INDEX('Eredmény'!$AT$2:$AT$201,$W12)) | T12: =IF($W12="","",INDEX('Eredmény'!$AV$2:$AV$201,$W12)) | U12: =IF($W12="","",INDEX('Eredmény'!$BI$2:$BI$201,$W12)) | W12: =IFERROR(MATCH(LARGE('Eredmény'!$DY$2:$DY$201,8),'Eredmény'!$DY$2:$DY$201,0),"")
A13: =IF($W13="","",INDEX('Eredmény'!$AO$2:$AO$201,$W13)) | B13: =IF($W13="","",INDEX('Eredmény'!$A$2:$A$201,$W13)) | C13: =IF($W13="","",INDEX('Eredmény'!$AM$2:$AM$201,$W13)) | D13: =IF($W13="","",INDEX('Eredmény'!$AN$2:$AN$201,$W13)) | E13: =IF($W13="","",INDEX('Eredmény'!$AQ$2:$AQ$201,$W13)) | F13: =IF($W13="","",INDEX('Eredmény'!$AR$2:$AR$201,$W13)) | G13: =IF($W13="","",INDEX('Eredmény'!$AS$2:$AS$201,$W13)) | H13: =IF($W13="","",INDEX('Eredmény'!$AI$2:$AI$201,$W13)) | I13: =IF($W13="","",INDEX('Eredmény'!$AJ$2:$AJ$201,$W13)) | J13: =IF($W13="","",INDEX('Eredmény'!$AK$2:$AK$201,$W13)) | K13: =IF($W13="","",INDEX('Eredmény'!$AL$2:$AL$201,$W13)) | L13: =IF($W13="","",INDEX('Eredmény'!$AZ$2:$AZ$201,$W13)) | M13: =IF($W13="","",INDEX('Eredmény'!$BB$2:$BB$201,$W13)) | N13: =IF($W13="","",INDEX('Eredmény'!$BC$2:$BC$201,$W13)) | O13: =IF($W13="","",INDEX('Eredmény'!$BD$2:$BD$201,$W13)) | P13: =IF($W13="","",INDEX('Eredmény'!$BE$2:$BE$201,$W13)) | Q13: =IF($W13="","",INDEX('Eredmény'!$BF$2:$BF$201,$W13)) | R13: =IF($W13="","",INDEX('Eredmény'!$BG$2:$BG$201,$W13)) | S13: =IF($W13="","",INDEX('Eredmény'!$AT$2:$AT$201,$W13)) | T13: =IF($W13="","",INDEX('Eredmény'!$AV$2:$AV$201,$W13)) | U13: =IF($W13="","",INDEX('Eredmény'!$BI$2:$BI$201,$W13)) | W13: =IFERROR(MATCH(LARGE('Eredmény'!$DY$2:$DY$201,9),'Eredmény'!$DY$2:$DY$201,0),"")
A14: =IF($W14="","",INDEX('Eredmény'!$AO$2:$AO$201,$W14)) | B14: =IF($W14="","",INDEX('Eredmény'!$A$2:$A$201,$W14)) | C14: =IF($W14="","",INDEX('Eredmény'!$AM$2:$AM$201,$W14)) | D14: =IF($W14="","",INDEX('Eredmény'!$AN$2:$AN$201,$W14)) | E14: =IF($W14="","",INDEX('Eredmény'!$AQ$2:$AQ$201,$W14)) | F14: =IF($W14="","",INDEX('Eredmény'!$AR$2:$AR$201,$W14)) | G14: =IF($W14="","",INDEX('Eredmény'!$AS$2:$AS$201,$W14)) | H14: =IF($W14="","",INDEX('Eredmény'!$AI$2:$AI$201,$W14)) | I14: =IF($W14="","",INDEX('Eredmény'!$AJ$2:$AJ$201,$W14)) | J14: =IF($W14="","",INDEX('Eredmény'!$AK$2:$AK$201,$W14)) | K14: =IF($W14="","",INDEX('Eredmény'!$AL$2:$AL$201,$W14)) | L14: =IF($W14="","",INDEX('Eredmény'!$AZ$2:$AZ$201,$W14)) | M14: =IF($W14="","",INDEX('Eredmény'!$BB$2:$BB$201,$W14)) | N14: =IF($W14="","",INDEX('Eredmény'!$BC$2:$BC$201,$W14)) | O14: =IF($W14="","",INDEX('Eredmény'!$BD$2:$BD$201,$W14)) | P14: =IF($W14="","",INDEX('Eredmény'!$BE$2:$BE$201,$W14)) | Q14: =IF($W14="","",INDEX('Eredmény'!$BF$2:$BF$201,$W14)) | R14: =IF($W14="","",INDEX('Eredmény'!$BG$2:$BG$201,$W14)) | S14: =IF($W14="","",INDEX('Eredmény'!$AT$2:$AT$201,$W14)) | T14: =IF($W14="","",INDEX('Eredmény'!$AV$2:$AV$201,$W14)) | U14: =IF($W14="","",INDEX('Eredmény'!$BI$2:$BI$201,$W14)) | W14: =IFERROR(MATCH(LARGE('Eredmény'!$DY$2:$DY$201,10),'Eredmény'!$DY$2:$DY$201,0),"")
A15: =IF($W15="","",INDEX('Eredmény'!$AO$2:$AO$201,$W15)) | B15: =IF($W15="","",INDEX('Eredmény'!$A$2:$A$201,$W15)) | C15: =IF($W15="","",INDEX('Eredmény'!$AM$2:$AM$201,$W15)) | D15: =IF($W15="","",INDEX('Eredmény'!$AN$2:$AN$201,$W15)) | E15: =IF($W15="","",INDEX('Eredmény'!$AQ$2:$AQ$201,$W15)) | F15: =IF($W15="","",INDEX('Eredmény'!$AR$2:$AR$201,$W15)) | G15: =IF($W15="","",INDEX('Eredmény'!$AS$2:$AS$201,$W15)) | H15: =IF($W15="","",INDEX('Eredmény'!$AI$2:$AI$201,$W15)) | I15: =IF($W15="","",INDEX('Eredmény'!$AJ$2:$AJ$201,$W15)) | J15: =IF($W15="","",INDEX('Eredmény'!$AK$2:$AK$201,$W15)) | K15: =IF($W15="","",INDEX('Eredmény'!$AL$2:$AL$201,$W15)) | L15: =IF($W15="","",INDEX('Eredmény'!$AZ$2:$AZ$201,$W15)) | M15: =IF($W15="","",INDEX('Eredmény'!$BB$2:$BB$201,$W15)) | N15: =IF($W15="","",INDEX('Eredmény'!$BC$2:$BC$201,$W15)) | O15: =IF($W15="","",INDEX('Eredmény'!$BD$2:$BD$201,$W15)) | P15: =IF($W15="","",INDEX('Eredmény'!$BE$2:$BE$201,$W15)) | Q15: =IF($W15="","",INDEX('Eredmény'!$BF$2:$BF$201,$W15)) | R15: =IF($W15="","",INDEX('Eredmény'!$BG$2:$BG$201,$W15)) | S15: =IF($W15="","",INDEX('Eredmény'!$AT$2:$AT$201,$W15)) | T15: =IF($W15="","",INDEX('Eredmény'!$AV$2:$AV$201,$W15)) | U15: =IF($W15="","",INDEX('Eredmény'!$BI$2:$BI$201,$W15)) | W15: =IFERROR(MATCH(LARGE('Eredmény'!$DY$2:$DY$201,11),'Eredmény'!$DY$2:$DY$201,0),"")
A16: =IF($W16="","",INDEX('Eredmény'!$AO$2:$AO$201,$W16)) | B16: =IF($W16="","",INDEX('Eredmény'!$A$2:$A$201,$W16)) | C16: =IF($W16="","",INDEX('Eredmény'!$AM$2:$AM$201,$W16)) | D16: =IF($W16="","",INDEX('Eredmény'!$AN$2:$AN$201,$W16)) | E16: =IF($W16="","",INDEX('Eredmény'!$AQ$2:$AQ$201,$W16)) | F16: =IF($W16="","",INDEX('Eredmény'!$AR$2:$AR$201,$W16)) | G16: =IF($W16="","",INDEX('Eredmény'!$AS$2:$AS$201,$W16)) | H16: =IF($W16="","",INDEX('Eredmény'!$AI$2:$AI$201,$W16)) | I16: =IF($W16="","",INDEX('Eredmény'!$AJ$2:$AJ$201,$W16)) | J16: =IF($W16="","",INDEX('Eredmény'!$AK$2:$AK$201,$W16)) | K16: =IF($W16="","",INDEX('Eredmény'!$AL$2:$AL$201,$W16)) | L16: =IF($W16="","",INDEX('Eredmény'!$AZ$2:$AZ$201,$W16)) | M16: =IF($W16="","",INDEX('Eredmény'!$BB$2:$BB$201,$W16)) | N16: =IF($W16="","",INDEX('Eredmény'!$BC$2:$BC$201,$W16)) | O16: =IF($W16="","",INDEX('Eredmény'!$BD$2:$BD$201,$W16)) | P16: =IF($W16="","",INDEX('Eredmény'!$BE$2:$BE$201,$W16)) | Q16: =IF($W16="","",INDEX('Eredmény'!$BF$2:$BF$201,$W16)) | R16: =IF($W16="","",INDEX('Eredmény'!$BG$2:$BG$201,$W16)) | S16: =IF($W16="","",INDEX('Eredmény'!$AT$2:$AT$201,$W16)) | T16: =IF($W16="","",INDEX('Eredmény'!$AV$2:$AV$201,$W16)) | U16: =IF($W16="","",INDEX('Eredmény'!$BI$2:$BI$201,$W16)) | W16: =IFERROR(MATCH(LARGE('Eredmény'!$DY$2:$DY$201,12),'Eredmény'!$DY$2:$DY$201,0),"")
A17: =IF($W17="","",INDEX('Eredmény'!$AO$2:$AO$201,$W17)) | B17: =IF($W17="","",INDEX('Eredmény'!$A$2:$A$201,$W17)) | C17: =IF($W17="","",INDEX('Eredmény'!$AM$2:$AM$201,$W17)) | D17: =IF($W17="","",INDEX('Eredmény'!$AN$2:$AN$201,$W17)) | E17: =IF($W17="","",INDEX('Eredmény'!$AQ$2:$AQ$201,$W17)) | F17: =IF($W17="","",INDEX('Eredmény'!$AR$2:$AR$201,$W17)) | G17: =IF($W17="","",INDEX('Eredmény'!$AS$2:$AS$201,$W17)) | H17: =IF($W17="","",INDEX('Eredmény'!$AI$2:$AI$201,$W17)) | I17: =IF($W17="","",INDEX('Eredmény'!$AJ$2:$AJ$201,$W17)) | J17: =IF($W17="","",INDEX('Eredmény'!$AK$2:$AK$201,$W17)) | K17: =IF($W17="","",INDEX('Eredmény'!$AL$2:$AL$201,$W17)) | L17: =IF($W17="","",INDEX('Eredmény'!$AZ$2:$AZ$201,$W17)) | M17: =IF($W17="","",INDEX('Eredmény'!$BB$2:$BB$201,$W17)) | N17: =IF($W17="","",INDEX('Eredmény'!$BC$2:$BC$201,$W17)) | O17: =IF($W17="","",INDEX('Eredmény'!$BD$2:$BD$201,$W17)) | P17: =IF($W17="","",INDEX('Eredmény'!$BE$2:$BE$201,$W17)) | Q17: =IF($W17="","",INDEX('Eredmény'!$BF$2:$BF$201,$W17)) | R17: =IF($W17="","",INDEX('Eredmény'!$BG$2:$BG$201,$W17)) | S17: =IF($W17="","",INDEX('Eredmény'!$AT$2:$AT$201,$W17)) | T17: =IF($W17="","",INDEX('Eredmény'!$AV$2:$AV$201,$W17)) | U17: =IF($W17="","",INDEX('Eredmény'!$BI$2:$BI$201,$W17)) | W17: =IFERROR(MATCH(LARGE('Eredmény'!$DY$2:$DY$201,13),'Eredmény'!$DY$2:$DY$201,0),"")
A18: =IF($W18="","",INDEX('Eredmény'!$AO$2:$AO$201,$W18)) | B18: =IF($W18="","",INDEX('Eredmény'!$A$2:$A$201,$W18)) | C18: =IF($W18="","",INDEX('Eredmény'!$AM$2:$AM$201,$W18)) | D18: =IF($W18="","",INDEX('Eredmény'!$AN$2:$AN$201,$W18)) | E18: =IF($W18="","",INDEX('Eredmény'!$AQ$2:$AQ$201,$W18)) | F18: =IF($W18="","",INDEX('Eredmény'!$AR$2:$AR$201,$W18)) | G18: =IF($W18="","",INDEX('Eredmény'!$AS$2:$AS$201,$W18)) | H18: =IF($W18="","",INDEX('Eredmény'!$AI$2:$AI$201,$W18)) | I18: =IF($W18="","",INDEX('Eredmény'!$AJ$2:$AJ$201,$W18)) | J18: =IF($W18="","",INDEX('Eredmény'!$AK$2:$AK$201,$W18)) | K18: =IF($W18="","",INDEX('Eredmény'!$AL$2:$AL$201,$W18)) | L18: =IF($W18="","",INDEX('Eredmény'!$AZ$2:$AZ$201,$W18)) | M18: =IF($W18="","",INDEX('Eredmény'!$BB$2:$BB$201,$W18)) | N18: =IF($W18="","",INDEX('Eredmény'!$BC$2:$BC$201,$W18)) | O18: =IF($W18="","",INDEX('Eredmény'!$BD$2:$BD$201,$W18)) | P18: =IF($W18="","",INDEX('Eredmény'!$BE$2:$BE$201,$W18)) | Q18: =IF($W18="","",INDEX('Eredmény'!$BF$2:$BF$201,$W18)) | R18: =IF($W18="","",INDEX('Eredmény'!$BG$2:$BG$201,$W18)) | S18: =IF($W18="","",INDEX('Eredmény'!$AT$2:$AT$201,$W18)) | T18: =IF($W18="","",INDEX('Eredmény'!$AV$2:$AV$201,$W18)) | U18: =IF($W18="","",INDEX('Eredmény'!$BI$2:$BI$201,$W18)) | W18: =IFERROR(MATCH(LARGE('Eredmény'!$DY$2:$DY$201,14),'Eredmény'!$DY$2:$DY$201,0),"")
A19: =IF($W19="","",INDEX('Eredmény'!$AO$2:$AO$201,$W19)) | B19: =IF($W19="","",INDEX('Eredmény'!$A$2:$A$201,$W19)) | C19: =IF($W19="","",INDEX('Eredmény'!$AM$2:$AM$201,$W19)) | D19: =IF($W19="","",INDEX('Eredmény'!$AN$2:$AN$201,$W19)) | E19: =IF($W19="","",INDEX('Eredmény'!$AQ$2:$AQ$201,$W19)) | F19: =IF($W19="","",INDEX('Eredmény'!$AR$2:$AR$201,$W19)) | G19: =IF($W19="","",INDEX('Eredmény'!$AS$2:$AS$201,$W19)) | H19: =IF($W19="","",INDEX('Eredmény'!$AI$2:$AI$201,$W19)) | I19: =IF($W19="","",INDEX('Eredmény'!$AJ$2:$AJ$201,$W19)) | J19: =IF($W19="","",INDEX('Eredmény'!$AK$2:$AK$201,$W19)) | K19: =IF($W19="","",INDEX('Eredmény'!$AL$2:$AL$201,$W19)) | L19: =IF($W19="","",INDEX('Eredmény'!$AZ$2:$AZ$201,$W19)) | M19: =IF($W19="","",INDEX('Eredmény'!$BB$2:$BB$201,$W19)) | N19: =IF($W19="","",INDEX('Eredmény'!$BC$2:$BC$201,$W19)) | O19: =IF($W19="","",INDEX('Eredmény'!$BD$2:$BD$201,$W19)) | P19: =IF($W19="","",INDEX('Eredmény'!$BE$2:$BE$201,$W19)) | Q19: =IF($W19="","",INDEX('Eredmény'!$BF$2:$BF$201,$W19)) | R19: =IF($W19="","",INDEX('Eredmény'!$BG$2:$BG$201,$W19)) | S19: =IF($W19="","",INDEX('Eredmény'!$AT$2:$AT$201,$W19)) | T19: =IF($W19="","",INDEX('Eredmény'!$AV$2:$AV$201,$W19)) | U19: =IF($W19="","",INDEX('Eredmény'!$BI$2:$BI$201,$W19)) | W19: =IFERROR(MATCH(LARGE('Eredmény'!$DY$2:$DY$201,15),'Eredmény'!$DY$2:$DY$201,0),"")
A20: =IF($W20="","",INDEX('Eredmény'!$AO$2:$AO$201,$W20)) | B20: =IF($W20="","",INDEX('Eredmény'!$A$2:$A$201,$W20)) | C20: =IF($W20="","",INDEX('Eredmény'!$AM$2:$AM$201,$W20)) | D20: =IF($W20="","",INDEX('Eredmény'!$AN$2:$AN$201,$W20)) | E20: =IF($W20="","",INDEX('Eredmény'!$AQ$2:$AQ$201,$W20)) | F20: =IF($W20="","",INDEX('Eredmény'!$AR$2:$AR$201,$W20)) | G20: =IF($W20="","",INDEX('Eredmény'!$AS$2:$AS$201,$W20)) | H20: =IF($W20="","",INDEX('Eredmény'!$AI$2:$AI$201,$W20)) | I20: =IF($W20="","",INDEX('Eredmény'!$AJ$2:$AJ$201,$W20)) | J20: =IF($W20="","",INDEX('Eredmény'!$AK$2:$AK$201,$W20)) | K20: =IF($W20="","",INDEX('Eredmény'!$AL$2:$AL$201,$W20)) | L20: =IF($W20="","",INDEX('Eredmény'!$AZ$2:$AZ$201,$W20)) | M20: =IF($W20="","",INDEX('Eredmény'!$BB$2:$BB$201,$W20)) | N20: =IF($W20="","",INDEX('Eredmény'!$BC$2:$BC$201,$W20)) | O20: =IF($W20="","",INDEX('Eredmény'!$BD$2:$BD$201,$W20)) | P20: =IF($W20="","",INDEX('Eredmény'!$BE$2:$BE$201,$W20)) | Q20: =IF($W20="","",INDEX('Eredmény'!$BF$2:$BF$201,$W20)) | R20: =IF($W20="","",INDEX('Eredmény'!$BG$2:$BG$201,$W20)) | S20: =IF($W20="","",INDEX('Eredmény'!$AT$2:$AT$201,$W20)) | T20: =IF($W20="","",INDEX('Eredmény'!$AV$2:$AV$201,$W20)) | U20: =IF($W20="","",INDEX('Eredmény'!$BI$2:$BI$201,$W20)) | W20: =IFERROR(MATCH(LARGE('Eredmény'!$DY$2:$DY$201,16),'Eredmény'!$DY$2:$DY$201,0),"")
A21: =IF($W21="","",INDEX('Eredmény'!$AO$2:$AO$201,$W21)) | B21: =IF($W21="","",INDEX('Eredmény'!$A$2:$A$201,$W21)) | C21: =IF($W21="","",INDEX('Eredmény'!$AM$2:$AM$201,$W21)) | D21: =IF($W21="","",INDEX('Eredmény'!$AN$2:$AN$201,$W21)) | E21: =IF($W21="","",INDEX('Eredmény'!$AQ$2:$AQ$201,$W21)) | F21: =IF($W21="","",INDEX('Eredmény'!$AR$2:$AR$201,$W21)) | G21: =IF($W21="","",INDEX('Eredmény'!$AS$2:$AS$201,$W21)) | H21: =IF($W21="","",INDEX('Eredmény'!$AI$2:$AI$201,$W21)) | I21: =IF($W21="","",INDEX('Eredmény'!$AJ$2:$AJ$201,$W21)) | J21: =IF($W21="","",INDEX('Eredmény'!$AK$2:$AK$201,$W21)) | K21: =IF($W21="","",INDEX('Eredmény'!$AL$2:$AL$201,$W21)) | L21: =IF($W21="","",INDEX('Eredmény'!$AZ$2:$AZ$201,$W21)) | M21: =IF($W21="","",INDEX('Eredmény'!$BB$2:$BB$201,$W21)) | N21: =IF($W21="","",INDEX('Eredmény'!$BC$2:$BC$201,$W21)) | O21: =IF($W21="","",INDEX('Eredmény'!$BD$2:$BD$201,$W21)) | P21: =IF($W21="","",INDEX('Eredmény'!$BE$2:$BE$201,$W21)) | Q21: =IF($W21="","",INDEX('Eredmény'!$BF$2:$BF$201,$W21)) | R21: =IF($W21="","",INDEX('Eredmény'!$BG$2:$BG$201,$W21)) | S21: =IF($W21="","",INDEX('Eredmény'!$AT$2:$AT$201,$W21)) | T21: =IF($W21="","",INDEX('Eredmény'!$AV$2:$AV$201,$W21)) | U21: =IF($W21="","",INDEX('Eredmény'!$BI$2:$BI$201,$W21)) | W21: =IFERROR(MATCH(LARGE('Eredmény'!$DY$2:$DY$201,17),'Eredmény'!$DY$2:$DY$201,0),"")
A22: =IF($W22="","",INDEX('Eredmény'!$AO$2:$AO$201,$W22)) | B22: =IF($W22="","",INDEX('Eredmény'!$A$2:$A$201,$W22)) | C22: =IF($W22="","",INDEX('Eredmény'!$AM$2:$AM$201,$W22)) | D22: =IF($W22="","",INDEX('Eredmény'!$AN$2:$AN$201,$W22)) | E22: =IF($W22="","",INDEX('Eredmény'!$AQ$2:$AQ$201,$W22)) | F22: =IF($W22="","",INDEX('Eredmény'!$AR$2:$AR$201,$W22)) | G22: =IF($W22="","",INDEX('Eredmény'!$AS$2:$AS$201,$W22)) | H22: =IF($W22="","",INDEX('Eredmény'!$AI$2:$AI$201,$W22)) | I22: =IF($W22="","",INDEX('Eredmény'!$AJ$2:$AJ$201,$W22)) | J22: =IF($W22="","",INDEX('Eredmény'!$AK$2:$AK$201,$W22)) | K22: =IF($W22="","",INDEX('Eredmény'!$AL$2:$AL$201,$W22)) | L22: =IF($W22="","",INDEX('Eredmény'!$AZ$2:$AZ$201,$W22)) | M22: =IF($W22="","",INDEX('Eredmény'!$BB$2:$BB$201,$W22)) | N22: =IF($W22="","",INDEX('Eredmény'!$BC$2:$BC$201,$W22)) | O22: =IF($W22="","",INDEX('Eredmény'!$BD$2:$BD$201,$W22)) | P22: =IF($W22="","",INDEX('Eredmény'!$BE$2:$BE$201,$W22)) | Q22: =IF($W22="","",INDEX('Eredmény'!$BF$2:$BF$201,$W22)) | R22: =IF($W22="","",INDEX('Eredmény'!$BG$2:$BG$201,$W22)) | S22: =IF($W22="","",INDEX('Eredmény'!$AT$2:$AT$201,$W22)) | T22: =IF($W22="","",INDEX('Eredmény'!$AV$2:$AV$201,$W22)) | U22: =IF($W22="","",INDEX('Eredmény'!$BI$2:$BI$201,$W22)) | W22: =IFERROR(MATCH(LARGE('Eredmény'!$DY$2:$DY$201,18),'Eredmény'!$DY$2:$DY$201,0),"")
A23: =IF($W23="","",INDEX('Eredmény'!$AO$2:$AO$201,$W23)) | B23: =IF($W23="","",INDEX('Eredmény'!$A$2:$A$201,$W23)) | C23: =IF($W23="","",INDEX('Eredmény'!$AM$2:$AM$201,$W23)) | D23: =IF($W23="","",INDEX('Eredmény'!$AN$2:$AN$201,$W23)) | E23: =IF($W23="","",INDEX('Eredmény'!$AQ$2:$AQ$201,$W23)) | F23: =IF($W23="","",INDEX('Eredmény'!$AR$2:$AR$201,$W23)) | G23: =IF($W23="","",INDEX('Eredmény'!$AS$2:$AS$201,$W23)) | H23: =IF($W23="","",INDEX('Eredmény'!$AI$2:$AI$201,$W23)) | I23: =IF($W23="","",INDEX('Eredmény'!$AJ$2:$AJ$201,$W23)) | J23: =IF($W23="","",INDEX('Eredmény'!$AK$2:$AK$201,$W23)) | K23: =IF($W23="","",INDEX('Eredmény'!$AL$2:$AL$201,$W23)) | L23: =IF($W23="","",INDEX('Eredmény'!$AZ$2:$AZ$201,$W23)) | M23: =IF($W23="","",INDEX('Eredmény'!$BB$2:$BB$201,$W23)) | N23: =IF($W23="","",INDEX('Eredmény'!$BC$2:$BC$201,$W23)) | O23: =IF($W23="","",INDEX('Eredmény'!$BD$2:$BD$201,$W23)) | P23: =IF($W23="","",INDEX('Eredmény'!$BE$2:$BE$201,$W23)) | Q23: =IF($W23="","",INDEX('Eredmény'!$BF$2:$BF$201,$W23)) | R23: =IF($W23="","",INDEX('Eredmény'!$BG$2:$BG$201,$W23)) | S23: =IF($W23="","",INDEX('Eredmény'!$AT$2:$AT$201,$W23)) | T23: =IF($W23="","",INDEX('Eredmény'!$AV$2:$AV$201,$W23)) | U23: =IF($W23="","",INDEX('Eredmény'!$BI$2:$BI$201,$W23)) | W23: =IFERROR(MATCH(LARGE('Eredmény'!$DY$2:$DY$201,19),'Eredmény'!$DY$2:$DY$201,0),"")
A24: =IF($W24="","",INDEX('Eredmény'!$AO$2:$AO$201,$W24)) | B24: =IF($W24="","",INDEX('Eredmény'!$A$2:$A$201,$W24)) | C24: =IF($W24="","",INDEX('Eredmény'!$AM$2:$AM$201,$W24)) | D24: =IF($W24="","",INDEX('Eredmény'!$AN$2:$AN$201,$W24)) | E24: =IF($W24="","",INDEX('Eredmény'!$AQ$2:$AQ$201,$W24)) | F24: =IF($W24="","",INDEX('Eredmény'!$AR$2:$AR$201,$W24)) | G24: =IF($W24="","",INDEX('Eredmény'!$AS$2:$AS$201,$W24)) | H24: =IF($W24="","",INDEX('Eredmény'!$AI$2:$AI$201,$W24)) | I24: =IF($W24="","",INDEX('Eredmény'!$AJ$2:$AJ$201,$W24)) | J24: =IF($W24="","",INDEX('Eredmény'!$AK$2:$AK$201,$W24)) | K24: =IF($W24="","",INDEX('Eredmény'!$AL$2:$AL$201,$W24)) | L24: =IF($W24="","",INDEX('Eredmény'!$AZ$2:$AZ$201,$W24)) | M24: =IF($W24="","",INDEX('Eredmény'!$BB$2:$BB$201,$W24)) | N24: =IF($W24="","",INDEX('Eredmény'!$BC$2:$BC$201,$W24)) | O24: =IF($W24="","",INDEX('Eredmény'!$BD$2:$BD$201,$W24)) | P24: =IF($W24="","",INDEX('Eredmény'!$BE$2:$BE$201,$W24)) | Q24: =IF($W24="","",INDEX('Eredmény'!$BF$2:$BF$201,$W24)) | R24: =IF($W24="","",INDEX('Eredmény'!$BG$2:$BG$201,$W24)) | S24: =IF($W24="","",INDEX('Eredmény'!$AT$2:$AT$201,$W24)) | T24: =IF($W24="","",INDEX('Eredmény'!$AV$2:$AV$201,$W24)) | U24: =IF($W24="","",INDEX('Eredmény'!$BI$2:$BI$201,$W24)) | W24: =IFERROR(MATCH(LARGE('Eredmény'!$DY$2:$DY$201,20),'Eredmény'!$DY$2:$DY$201,0),"")
A25: =IF($W25="","",INDEX('Eredmény'!$AO$2:$AO$201,$W25)) | B25: =IF($W25="","",INDEX('Eredmény'!$A$2:$A$201,$W25)) | C25: =IF($W25="","",INDEX('Eredmény'!$AM$2:$AM$201,$W25)) | D25: =IF($W25="","",INDEX('Eredmény'!$AN$2:$AN$201,$W25)) | E25: =IF($W25="","",INDEX('Eredmény'!$AQ$2:$AQ$201,$W25)) | F25: =IF($W25="","",INDEX('Eredmény'!$AR$2:$AR$201,$W25)) | G25: =IF($W25="","",INDEX('Eredmény'!$AS$2:$AS$201,$W25)) | H25: =IF($W25="","",INDEX('Eredmény'!$AI$2:$AI$201,$W25)) | I25: =IF($W25="","",INDEX('Eredmény'!$AJ$2:$AJ$201,$W25)) | J25: =IF($W25="","",INDEX('Eredmény'!$AK$2:$AK$201,$W25)) | K25: =IF($W25="","",INDEX('Eredmény'!$AL$2:$AL$201,$W25)) | L25: =IF($W25="","",INDEX('Eredmény'!$AZ$2:$AZ$201,$W25)) | M25: =IF($W25="","",INDEX('Eredmény'!$BB$2:$BB$201,$W25)) | N25: =IF($W25="","",INDEX('Eredmény'!$BC$2:$BC$201,$W25)) | O25: =IF($W25="","",INDEX('Eredmény'!$BD$2:$BD$201,$W25)) | P25: =IF($W25="","",INDEX('Eredmény'!$BE$2:$BE$201,$W25)) | Q25: =IF($W25="","",INDEX('Eredmény'!$BF$2:$BF$201,$W25)) | R25: =IF($W25="","",INDEX('Eredmény'!$BG$2:$BG$201,$W25)) | S25: =IF($W25="","",INDEX('Eredmény'!$AT$2:$AT$201,$W25)) | T25: =IF($W25="","",INDEX('Eredmény'!$AV$2:$AV$201,$W25)) | U25: =IF($W25="","",INDEX('Eredmény'!$BI$2:$BI$201,$W25)) | W25: =IFERROR(MATCH(LARGE('Eredmény'!$DY$2:$DY$201,21),'Eredmény'!$DY$2:$DY$201,0),"")
A26: =IF($W26="","",INDEX('Eredmény'!$AO$2:$AO$201,$W26)) | B26: =IF($W26="","",INDEX('Eredmény'!$A$2:$A$201,$W26)) | C26: =IF($W26="","",INDEX('Eredmény'!$AM$2:$AM$201,$W26)) | D26: =IF($W26="","",INDEX('Eredmény'!$AN$2:$AN$201,$W26)) | E26: =IF($W26="","",INDEX('Eredmény'!$AQ$2:$AQ$201,$W26)) | F26: =IF($W26="","",INDEX('Eredmény'!$AR$2:$AR$201,$W26)) | G26: =IF($W26="","",INDEX('Eredmény'!$AS$2:$AS$201,$W26)) | H26: =IF($W26="","",INDEX('Eredmény'!$AI$2:$AI$201,$W26)) | I26: =IF($W26="","",INDEX('Eredmény'!$AJ$2:$AJ$201,$W26)) | J26: =IF($W26="","",INDEX('Eredmény'!$AK$2:$AK$201,$W26)) | K26: =IF($W26="","",INDEX('Eredmény'!$AL$2:$AL$201,$W26)) | L26: =IF($W26="","",INDEX('Eredmény'!$AZ$2:$AZ$201,$W26)) | M26: =IF($W26="","",INDEX('Eredmény'!$BB$2:$BB$201,$W26)) | N26: =IF($W26="","",INDEX('Eredmény'!$BC$2:$BC$201,$W26)) | O26: =IF($W26="","",INDEX('Eredmény'!$BD$2:$BD$201,$W26)) | P26: =IF($W26="","",INDEX('Eredmény'!$BE$2:$BE$201,$W26)) | Q26: =IF($W26="","",INDEX('Eredmény'!$BF$2:$BF$201,$W26)) | R26: =IF($W26="","",INDEX('Eredmény'!$BG$2:$BG$201,$W26)) | S26: =IF($W26="","",INDEX('Eredmény'!$AT$2:$AT$201,$W26)) | T26: =IF($W26="","",INDEX('Eredmény'!$AV$2:$AV$201,$W26)) | U26: =IF($W26="","",INDEX('Eredmény'!$BI$2:$BI$201,$W26)) | W26: =IFERROR(MATCH(LARGE('Eredmény'!$DY$2:$DY$201,22),'Eredmény'!$DY$2:$DY$201,0),"")
A27: =IF($W27="","",INDEX('Eredmény'!$AO$2:$AO$201,$W27)) | B27: =IF($W27="","",INDEX('Eredmény'!$A$2:$A$201,$W27)) | C27: =IF($W27="","",INDEX('Eredmény'!$AM$2:$AM$201,$W27)) | D27: =IF($W27="","",INDEX('Eredmény'!$AN$2:$AN$201,$W27)) | E27: =IF($W27="","",INDEX('Eredmény'!$AQ$2:$AQ$201,$W27)) | F27: =IF($W27="","",INDEX('Eredmény'!$AR$2:$AR$201,$W27)) | G27: =IF($W27="","",INDEX('Eredmény'!$AS$2:$AS$201,$W27)) | H27: =IF($W27="","",INDEX('Eredmény'!$AI$2:$AI$201,$W27)) | I27: =IF($W27="","",INDEX('Eredmény'!$AJ$2:$AJ$201,$W27)) | J27: =IF($W27="","",INDEX('Eredmény'!$AK$2:$AK$201,$W27)) | K27: =IF($W27="","",INDEX('Eredmény'!$AL$2:$AL$201,$W27)) | L27: =IF($W27="","",INDEX('Eredmény'!$AZ$2:$AZ$201,$W27)) | M27: =IF($W27="","",INDEX('Eredmény'!$BB$2:$BB$201,$W27)) | N27: =IF($W27="","",INDEX('Eredmény'!$BC$2:$BC$201,$W27)) | O27: =IF($W27="","",INDEX('Eredmény'!$BD$2:$BD$201,$W27)) | P27: =IF($W27="","",INDEX('Eredmény'!$BE$2:$BE$201,$W27)) | Q27: =IF($W27="","",INDEX('Eredmény'!$BF$2:$BF$201,$W27)) | R27: =IF($W27="","",INDEX('Eredmény'!$BG$2:$BG$201,$W27)) | S27: =IF($W27="","",INDEX('Eredmény'!$AT$2:$AT$201,$W27)) | T27: =IF($W27="","",INDEX('Eredmény'!$AV$2:$AV$201,$W27)) | U27: =IF($W27="","",INDEX('Eredmény'!$BI$2:$BI$201,$W27)) | W27: =IFERROR(MATCH(LARGE('Eredmény'!$DY$2:$DY$201,23),'Eredmény'!$DY$2:$DY$201,0),"")
A28: =IF($W28="","",INDEX('Eredmény'!$AO$2:$AO$201,$W28)) | B28: =IF($W28="","",INDEX('Eredmény'!$A$2:$A$201,$W28)) | C28: =IF($W28="","",INDEX('Eredmény'!$AM$2:$AM$201,$W28)) | D28: =IF($W28="","",INDEX('Eredmény'!$AN$2:$AN$201,$W28)) | E28: =IF($W28="","",INDEX('Eredmény'!$AQ$2:$AQ$201,$W28)) | F28: =IF($W28="","",INDEX('Eredmény'!$AR$2:$AR$201,$W28)) | G28: =IF($W28="","",INDEX('Eredmény'!$AS$2:$AS$201,$W28)) | H28: =IF($W28="","",INDEX('Eredmény'!$AI$2:$AI$201,$W28)) | I28: =IF($W28="","",INDEX('Eredmény'!$AJ$2:$AJ$201,$W28)) | J28: =IF($W28="","",INDEX('Eredmény'!$AK$2:$AK$201,$W28)) | K28: =IF($W28="","",INDEX('Eredmény'!$AL$2:$AL$201,$W28)) | L28: =IF($W28="","",INDEX('Eredmény'!$AZ$2:$AZ$201,$W28)) | M28: =IF($W28="","",INDEX('Eredmény'!$BB$2:$BB$201,$W28)) | N28: =IF($W28="","",INDEX('Eredmény'!$BC$2:$BC$201,$W28)) | O28: =IF($W28="","",INDEX('Eredmény'!$BD$2:$BD$201,$W28)) | P28: =IF($W28="","",INDEX('Eredmény'!$BE$2:$BE$201,$W28)) | Q28: =IF($W28="","",INDEX('Eredmény'!$BF$2:$BF$201,$W28)) | R28: =IF($W28="","",INDEX('Eredmény'!$BG$2:$BG$201,$W28)) | S28: =IF($W28="","",INDEX('Eredmény'!$AT$2:$AT$201,$W28)) | T28: =IF($W28="","",INDEX('Eredmény'!$AV$2:$AV$201,$W28)) | U28: =IF($W28="","",INDEX('Eredmény'!$BI$2:$BI$201,$W28)) | W28: =IFERROR(MATCH(LARGE('Eredmény'!$DY$2:$DY$201,24),'Eredmény'!$DY$2:$DY$201,0),"")
A29: =IF($W29="","",INDEX('Eredmény'!$AO$2:$AO$201,$W29)) | B29: =IF($W29="","",INDEX('Eredmény'!$A$2:$A$201,$W29)) | C29: =IF($W29="","",INDEX('Eredmény'!$AM$2:$AM$201,$W29)) | D29: =IF($W29="","",INDEX('Eredmény'!$AN$2:$AN$201,$W29)) | E29: =IF($W29="","",INDEX('Eredmény'!$AQ$2:$AQ$201,$W29)) | F29: =IF($W29="","",INDEX('Eredmény'!$AR$2:$AR$201,$W29)) | G29: =IF($W29="","",INDEX('Eredmény'!$AS$2:$AS$201,$W29)) | H29: =IF($W29="","",INDEX('Eredmény'!$AI$2:$AI$201,$W29)) | I29: =IF($W29="","",INDEX('Eredmény'!$AJ$2:$AJ$201,$W29)) | J29: =IF($W29="","",INDEX('Eredmény'!$AK$2:$AK$201,$W29)) | K29: =IF($W29="","",INDEX('Eredmény'!$AL$2:$AL$201,$W29)) | L29: =IF($W29="","",INDEX('Eredmény'!$AZ$2:$AZ$201,$W29)) | M29: =IF($W29="","",INDEX('Eredmény'!$BB$2:$BB$201,$W29)) | N29: =IF($W29="","",INDEX('Eredmény'!$BC$2:$BC$201,$W29)) | O29: =IF($W29="","",INDEX('Eredmény'!$BD$2:$BD$201,$W29)) | P29: =IF($W29="","",INDEX('Eredmény'!$BE$2:$BE$201,$W29)) | Q29: =IF($W29="","",INDEX('Eredmény'!$BF$2:$BF$201,$W29)) | R29: =IF($W29="","",INDEX('Eredmény'!$BG$2:$BG$201,$W29)) | S29: =IF($W29="","",INDEX('Eredmény'!$AT$2:$AT$201,$W29)) | T29: =IF($W29="","",INDEX('Eredmény'!$AV$2:$AV$201,$W29)) | U29: =IF($W29="","",INDEX('Eredmény'!$BI$2:$BI$201,$W29)) | W29: =IFERROR(MATCH(LARGE('Eredmény'!$DY$2:$DY$201,25),'Eredmény'!$DY$2:$DY$201,0),"")
A30: =IF($W30="","",INDEX('Eredmény'!$AO$2:$AO$201,$W30)) | B30: =IF($W30="","",INDEX('Eredmény'!$A$2:$A$201,$W30)) | C30: =IF($W30="","",INDEX('Eredmény'!$AM$2:$AM$201,$W30)) | D30: =IF($W30="","",INDEX('Eredmény'!$AN$2:$AN$201,$W30)) | E30: =IF($W30="","",INDEX('Eredmény'!$AQ$2:$AQ$201,$W30)) | F30: =IF($W30="","",INDEX('Eredmény'!$AR$2:$AR$201,$W30)) | G30: =IF($W30="","",INDEX('Eredmény'!$AS$2:$AS$201,$W30)) | H30: =IF($W30="","",INDEX('Eredmény'!$AI$2:$AI$201,$W30)) | I30: =IF($W30="","",INDEX('Eredmény'!$AJ$2:$AJ$201,$W30)) | J30: =IF($W30="","",INDEX('Eredmény'!$AK$2:$AK$201,$W30)) | K30: =IF($W30="","",INDEX('Eredmény'!$AL$2:$AL$201,$W30)) | L30: =IF($W30="","",INDEX('Eredmény'!$AZ$2:$AZ$201,$W30)) | M30: =IF($W30="","",INDEX('Eredmény'!$BB$2:$BB$201,$W30)) | N30: =IF($W30="","",INDEX('Eredmény'!$BC$2:$BC$201,$W30)) | O30: =IF($W30="","",INDEX('Eredmény'!$BD$2:$BD$201,$W30)) | P30: =IF($W30="","",INDEX('Eredmény'!$BE$2:$BE$201,$W30)) | Q30: =IF($W30="","",INDEX('Eredmény'!$BF$2:$BF$201,$W30)) | R30: =IF($W30="","",INDEX('Eredmény'!$BG$2:$BG$201,$W30)) | S30: =IF($W30="","",INDEX('Eredmény'!$AT$2:$AT$201,$W30)) | T30: =IF($W30="","",INDEX('Eredmény'!$AV$2:$AV$201,$W30)) | U30: =IF($W30="","",INDEX('Eredmény'!$BI$2:$BI$201,$W30)) | W30: =IFERROR(MATCH(LARGE('Eredmény'!$DY$2:$DY$201,26),'Eredmény'!$DY$2:$DY$201,0),"")
A31: =IF($W31="","",INDEX('Eredmény'!$AO$2:$AO$201,$W31)) | B31: =IF($W31="","",INDEX('Eredmény'!$A$2:$A$201,$W31)) | C31: =IF($W31="","",INDEX('Eredmény'!$AM$2:$AM$201,$W31)) | D31: =IF($W31="","",INDEX('Eredmény'!$AN$2:$AN$201,$W31)) | E31: =IF($W31="","",INDEX('Eredmény'!$AQ$2:$AQ$201,$W31)) | F31: =IF($W31="","",INDEX('Eredmény'!$AR$2:$AR$201,$W31)) | G31: =IF($W31="","",INDEX('Eredmény'!$AS$2:$AS$201,$W31)) | H31: =IF($W31="","",INDEX('Eredmény'!$AI$2:$AI$201,$W31)) | I31: =IF($W31="","",INDEX('Eredmény'!$AJ$2:$AJ$201,$W31)) | J31: =IF($W31="","",INDEX('Eredmény'!$AK$2:$AK$201,$W31)) | K31: =IF($W31="","",INDEX('Eredmény'!$AL$2:$AL$201,$W31)) | L31: =IF($W31="","",INDEX('Eredmény'!$AZ$2:$AZ$201,$W31)) | M31: =IF($W31="","",INDEX('Eredmény'!$BB$2:$BB$201,$W31)) | N31: =IF($W31="","",INDEX('Eredmény'!$BC$2:$BC$201,$W31)) | O31: =IF($W31="","",INDEX('Eredmény'!$BD$2:$BD$201,$W31)) | P31: =IF($W31="","",INDEX('Eredmény'!$BE$2:$BE$201,$W31)) | Q31: =IF($W31="","",INDEX('Eredmény'!$BF$2:$BF$201,$W31)) | R31: =IF($W31="","",INDEX('Eredmény'!$BG$2:$BG$201,$W31)) | S31: =IF($W31="","",INDEX('Eredmény'!$AT$2:$AT$201,$W31)) | T31: =IF($W31="","",INDEX('Eredmény'!$AV$2:$AV$201,$W31)) | U31: =IF($W31="","",INDEX('Eredmény'!$BI$2:$BI$201,$W31)) | W31: =IFERROR(MATCH(LARGE('Eredmény'!$DY$2:$DY$201,27),'Eredmény'!$DY$2:$DY$201,0),"")
A32: =IF($W32="","",INDEX('Eredmény'!$AO$2:$AO$201,$W32)) | B32: =IF($W32="","",INDEX('Eredmény'!$A$2:$A$201,$W32)) | C32: =IF($W32="","",INDEX('Eredmény'!$AM$2:$AM$201,$W32)) | D32: =IF($W32="","",INDEX('Eredmény'!$AN$2:$AN$201,$W32)) | E32: =IF($W32="","",INDEX('Eredmény'!$AQ$2:$AQ$201,$W32)) | F32: =IF($W32="","",INDEX('Eredmény'!$AR$2:$AR$201,$W32)) | G32: =IF($W32="","",INDEX('Eredmény'!$AS$2:$AS$201,$W32)) | H32: =IF($W32="","",INDEX('Eredmény'!$AI$2:$AI$201,$W32)) | I32: =IF($W32="","",INDEX('Eredmény'!$AJ$2:$AJ$201,$W32)) | J32: =IF($W32="","",INDEX('Eredmény'!$AK$2:$AK$201,$W32)) | K32: =IF($W32="","",INDEX('Eredmény'!$AL$2:$AL$201,$W32)) | L32: =IF($W32="","",INDEX('Eredmény'!$AZ$2:$AZ$201,$W32)) | M32: =IF($W32="","",INDEX('Eredmény'!$BB$2:$BB$201,$W32)) | N32: =IF($W32="","",INDEX('Eredmény'!$BC$2:$BC$201,$W32)) | O32: =IF($W32="","",INDEX('Eredmény'!$BD$2:$BD$201,$W32)) | P32: =IF($W32="","",INDEX('Eredmény'!$BE$2:$BE$201,$W32)) | Q32: =IF($W32="","",INDEX('Eredmény'!$BF$2:$BF$201,$W32)) | R32: =IF($W32="","",INDEX('Eredmény'!$BG$2:$BG$201,$W32)) | S32: =IF($W32="","",INDEX('Eredmény'!$AT$2:$AT$201,$W32)) | T32: =IF($W32="","",INDEX('Eredmény'!$AV$2:$AV$201,$W32)) | U32: =IF($W32="","",INDEX('Eredmény'!$BI$2:$BI$201,$W32)) | W32: =IFERROR(MATCH(LARGE('Eredmény'!$DY$2:$DY$201,28),'Eredmény'!$DY$2:$DY$201,0),"")
A33: =IF($W33="","",INDEX('Eredmény'!$AO$2:$AO$201,$W33)) | B33: =IF($W33="","",INDEX('Eredmény'!$A$2:$A$201,$W33)) | C33: =IF($W33="","",INDEX('Eredmény'!$AM$2:$AM$201,$W33)) | D33: =IF($W33="","",INDEX('Eredmény'!$AN$2:$AN$201,$W33)) | E33: =IF($W33="","",INDEX('Eredmény'!$AQ$2:$AQ$201,$W33)) | F33: =IF($W33="","",INDEX('Eredmény'!$AR$2:$AR$201,$W33)) | G33: =IF($W33="","",INDEX('Eredmény'!$AS$2:$AS$201,$W33)) | H33: =IF($W33="","",INDEX('Eredmény'!$AI$2:$AI$201,$W33)) | I33: =IF($W33="","",INDEX('Eredmény'!$AJ$2:$AJ$201,$W33)) | J33: =IF($W33="","",INDEX('Eredmény'!$AK$2:$AK$201,$W33)) | K33: =IF($W33="","",INDEX('Eredmény'!$AL$2:$AL$201,$W33)) | L33: =IF($W33="","",INDEX('Eredmény'!$AZ$2:$AZ$201,$W33)) | M33: =IF($W33="","",INDEX('Eredmény'!$BB$2:$BB$201,$W33)) | N33: =IF($W33="","",INDEX('Eredmény'!$BC$2:$BC$201,$W33)) | O33: =IF($W33="","",INDEX('Eredmény'!$BD$2:$BD$201,$W33)) | P33: =IF($W33="","",INDEX('Eredmény'!$BE$2:$BE$201,$W33)) | Q33: =IF($W33="","",INDEX('Eredmény'!$BF$2:$BF$201,$W33)) | R33: =IF($W33="","",INDEX('Eredmény'!$BG$2:$BG$201,$W33)) | S33: =IF($W33="","",INDEX('Eredmény'!$AT$2:$AT$201,$W33)) | T33: =IF($W33="","",INDEX('Eredmény'!$AV$2:$AV$201,$W33)) | U33: =IF($W33="","",INDEX('Eredmény'!$BI$2:$BI$201,$W33)) | W33: =IFERROR(MATCH(LARGE('Eredmény'!$DY$2:$DY$201,29),'Eredmény'!$DY$2:$DY$201,0),"")
A34: =IF($W34="","",INDEX('Eredmény'!$AO$2:$AO$201,$W34)) | B34: =IF($W34="","",INDEX('Eredmény'!$A$2:$A$201,$W34)) | C34: =IF($W34="","",INDEX('Eredmény'!$AM$2:$AM$201,$W34)) | D34: =IF($W34="","",INDEX('Eredmény'!$AN$2:$AN$201,$W34)) | E34: =IF($W34="","",INDEX('Eredmény'!$AQ$2:$AQ$201,$W34)) | F34: =IF($W34="","",INDEX('Eredmény'!$AR$2:$AR$201,$W34)) | G34: =IF($W34="","",INDEX('Eredmény'!$AS$2:$AS$201,$W34)) | H34: =IF($W34="","",INDEX('Eredmény'!$AI$2:$AI$201,$W34)) | I34: =IF($W34="","",INDEX('Eredmény'!$AJ$2:$AJ$201,$W34)) | J34: =IF($W34="","",INDEX('Eredmény'!$AK$2:$AK$201,$W34)) | K34: =IF($W34="","",INDEX('Eredmény'!$AL$2:$AL$201,$W34)) | L34: =IF($W34="","",INDEX('Eredmény'!$AZ$2:$AZ$201,$W34)) | M34: =IF($W34="","",INDEX('Eredmény'!$BB$2:$BB$201,$W34)) | N34: =IF($W34="","",INDEX('Eredmény'!$BC$2:$BC$201,$W34)) | O34: =IF($W34="","",INDEX('Eredmény'!$BD$2:$BD$201,$W34)) | P34: =IF($W34="","",INDEX('Eredmény'!$BE$2:$BE$201,$W34)) | Q34: =IF($W34="","",INDEX('Eredmény'!$BF$2:$BF$201,$W34)) | R34: =IF($W34="","",INDEX('Eredmény'!$BG$2:$BG$201,$W34)) | S34: =IF($W34="","",INDEX('Eredmény'!$AT$2:$AT$201,$W34)) | T34: =IF($W34="","",INDEX('Eredmény'!$AV$2:$AV$201,$W34)) | U34: =IF($W34="","",INDEX('Eredmény'!$BI$2:$BI$201,$W34)) | W34: =IFERROR(MATCH(LARGE('Eredmény'!$DY$2:$DY$201,30),'Eredmény'!$DY$2:$DY$201,0),"")
A35: =IF($W35="","",INDEX('Eredmény'!$AO$2:$AO$201,$W35)) | B35: =IF($W35="","",INDEX('Eredmény'!$A$2:$A$201,$W35)) | C35: =IF($W35="","",INDEX('Eredmény'!$AM$2:$AM$201,$W35)) | D35: =IF($W35="","",INDEX('Eredmény'!$AN$2:$AN$201,$W35)) | E35: =IF($W35="","",INDEX('Eredmény'!$AQ$2:$AQ$201,$W35)) | F35: =IF($W35="","",INDEX('Eredmény'!$AR$2:$AR$201,$W35)) | G35: =IF($W35="","",INDEX('Eredmény'!$AS$2:$AS$201,$W35)) | H35: =IF($W35="","",INDEX('Eredmény'!$AI$2:$AI$201,$W35)) | I35: =IF($W35="","",INDEX('Eredmény'!$AJ$2:$AJ$201,$W35)) | J35: =IF($W35="","",INDEX('Eredmény'!$AK$2:$AK$201,$W35)) | K35: =IF($W35="","",INDEX('Eredmény'!$AL$2:$AL$201,$W35)) | L35: =IF($W35="","",INDEX('Eredmény'!$AZ$2:$AZ$201,$W35)) | M35: =IF($W35="","",INDEX('Eredmény'!$BB$2:$BB$201,$W35)) | N35: =IF($W35="","",INDEX('Eredmény'!$BC$2:$BC$201,$W35)) | O35: =IF($W35="","",INDEX('Eredmény'!$BD$2:$BD$201,$W35)) | P35: =IF($W35="","",INDEX('Eredmény'!$BE$2:$BE$201,$W35)) | Q35: =IF($W35="","",INDEX('Eredmény'!$BF$2:$BF$201,$W35)) | R35: =IF($W35="","",INDEX('Eredmény'!$BG$2:$BG$201,$W35)) | S35: =IF($W35="","",INDEX('Eredmény'!$AT$2:$AT$201,$W35)) | T35: =IF($W35="","",INDEX('Eredmény'!$AV$2:$AV$201,$W35)) | U35: =IF($W35="","",INDEX('Eredmény'!$BI$2:$BI$201,$W35)) | W35: =IFERROR(MATCH(LARGE('Eredmény'!$DY$2:$DY$201,31),'Eredmény'!$DY$2:$DY$201,0),"")
A36: =IF($W36="","",INDEX('Eredmény'!$AO$2:$AO$201,$W36)) | B36: =IF($W36="","",INDEX('Eredmény'!$A$2:$A$201,$W36)) | C36: =IF($W36="","",INDEX('Eredmény'!$AM$2:$AM$201,$W36)) | D36: =IF($W36="","",INDEX('Eredmény'!$AN$2:$AN$201,$W36)) | E36: =IF($W36="","",INDEX('Eredmény'!$AQ$2:$AQ$201,$W36)) | F36: =IF($W36="","",INDEX('Eredmény'!$AR$2:$AR$201,$W36)) | G36: =IF($W36="","",INDEX('Eredmény'!$AS$2:$AS$201,$W36)) | H36: =IF($W36="","",INDEX('Eredmény'!$AI$2:$AI$201,$W36)) | I36: =IF($W36="","",INDEX('Eredmény'!$AJ$2:$AJ$201,$W36)) | J36: =IF($W36="","",INDEX('Eredmény'!$AK$2:$AK$201,$W36)) | K36: =IF($W36="","",INDEX('Eredmény'!$AL$2:$AL$201,$W36)) | L36: =IF($W36="","",INDEX('Eredmény'!$AZ$2:$AZ$201,$W36)) | M36: =IF($W36="","",INDEX('Eredmény'!$BB$2:$BB$201,$W36)) | N36: =IF($W36="","",INDEX('Eredmény'!$BC$2:$BC$201,$W36)) | O36: =IF($W36="","",INDEX('Eredmény'!$BD$2:$BD$201,$W36)) | P36: =IF($W36="","",INDEX('Eredmény'!$BE$2:$BE$201,$W36)) | Q36: =IF($W36="","",INDEX('Eredmény'!$BF$2:$BF$201,$W36)) | R36: =IF($W36="","",INDEX('Eredmény'!$BG$2:$BG$201,$W36)) | S36: =IF($W36="","",INDEX('Eredmény'!$AT$2:$AT$201,$W36)) | T36: =IF($W36="","",INDEX('Eredmény'!$AV$2:$AV$201,$W36)) | U36: =IF($W36="","",INDEX('Eredmény'!$BI$2:$BI$201,$W36)) | W36: =IFERROR(MATCH(LARGE('Eredmény'!$DY$2:$DY$201,32),'Eredmény'!$DY$2:$DY$201,0),"")
A37: =IF($W37="","",INDEX('Eredmény'!$AO$2:$AO$201,$W37)) | B37: =IF($W37="","",INDEX('Eredmény'!$A$2:$A$201,$W37)) | C37: =IF($W37="","",INDEX('Eredmény'!$AM$2:$AM$201,$W37)) | D37: =IF($W37="","",INDEX('Eredmény'!$AN$2:$AN$201,$W37)) | E37: =IF($W37="","",INDEX('Eredmény'!$AQ$2:$AQ$201,$W37)) | F37: =IF($W37="","",INDEX('Eredmény'!$AR$2:$AR$201,$W37)) | G37: =IF($W37="","",INDEX('Eredmény'!$AS$2:$AS$201,$W37)) | H37: =IF($W37="","",INDEX('Eredmény'!$AI$2:$AI$201,$W37)) | I37: =IF($W37="","",INDEX('Eredmény'!$AJ$2:$AJ$201,$W37)) | J37: =IF($W37="","",INDEX('Eredmény'!$AK$2:$AK$201,$W37)) | K37: =IF($W37="","",INDEX('Eredmény'!$AL$2:$AL$201,$W37)) | L37: =IF($W37="","",INDEX('Eredmény'!$AZ$2:$AZ$201,$W37)) | M37: =IF($W37="","",INDEX('Eredmény'!$BB$2:$BB$201,$W37)) | N37: =IF($W37="","",INDEX('Eredmény'!$BC$2:$BC$201,$W37)) | O37: =IF($W37="","",INDEX('Eredmény'!$BD$2:$BD$201,$W37)) | P37: =IF($W37="","",INDEX('Eredmény'!$BE$2:$BE$201,$W37)) | Q37: =IF($W37="","",INDEX('Eredmény'!$BF$2:$BF$201,$W37)) | R37: =IF($W37="","",INDEX('Eredmény'!$BG$2:$BG$201,$W37)) | S37: =IF($W37="","",INDEX('Eredmény'!$AT$2:$AT$201,$W37)) | T37: =IF($W37="","",INDEX('Eredmény'!$AV$2:$AV$201,$W37)) | U37: =IF($W37="","",INDEX('Eredmény'!$BI$2:$BI$201,$W37)) | W37: =IFERROR(MATCH(LARGE('Eredmény'!$DY$2:$DY$201,33),'Eredmény'!$DY$2:$DY$201,0),"")
A38: =IF($W38="","",INDEX('Eredmény'!$AO$2:$AO$201,$W38)) | B38: =IF($W38="","",INDEX('Eredmény'!$A$2:$A$201,$W38)) | C38: =IF($W38="","",INDEX('Eredmény'!$AM$2:$AM$201,$W38)) | D38: =IF($W38="","",INDEX('Eredmény'!$AN$2:$AN$201,$W38)) | E38: =IF($W38="","",INDEX('Eredmény'!$AQ$2:$AQ$201,$W38)) | F38: =IF($W38="","",INDEX('Eredmény'!$AR$2:$AR$201,$W38)) | G38: =IF($W38="","",INDEX('Eredmény'!$AS$2:$AS$201,$W38)) | H38: =IF($W38="","",INDEX('Eredmény'!$AI$2:$AI$201,$W38)) | I38: =IF($W38="","",INDEX('Eredmény'!$AJ$2:$AJ$201,$W38)) | J38: =IF($W38="","",INDEX('Eredmény'!$AK$2:$AK$201,$W38)) | K38: =IF($W38="","",INDEX('Eredmény'!$AL$2:$AL$201,$W38)) | L38: =IF($W38="","",INDEX('Eredmény'!$AZ$2:$AZ$201,$W38)) | M38: =IF($W38="","",INDEX('Eredmény'!$BB$2:$BB$201,$W38)) | N38: =IF($W38="","",INDEX('Eredmény'!$BC$2:$BC$201,$W38)) | O38: =IF($W38="","",INDEX('Eredmény'!$BD$2:$BD$201,$W38)) | P38: =IF($W38="","",INDEX('Eredmény'!$BE$2:$BE$201,$W38)) | Q38: =IF($W38="","",INDEX('Eredmény'!$BF$2:$BF$201,$W38)) | R38: =IF($W38="","",INDEX('Eredmény'!$BG$2:$BG$201,$W38)) | S38: =IF($W38="","",INDEX('Eredmény'!$AT$2:$AT$201,$W38)) | T38: =IF($W38="","",INDEX('Eredmény'!$AV$2:$AV$201,$W38)) | U38: =IF($W38="","",INDEX('Eredmény'!$BI$2:$BI$201,$W38)) | W38: =IFERROR(MATCH(LARGE('Eredmény'!$DY$2:$DY$201,34),'Eredmény'!$DY$2:$DY$201,0),"")
A39: =IF($W39="","",INDEX('Eredmény'!$AO$2:$AO$201,$W39)) | B39: =IF($W39="","",INDEX('Eredmény'!$A$2:$A$201,$W39)) | C39: =IF($W39="","",INDEX('Eredmény'!$AM$2:$AM$201,$W39)) | D39: =IF($W39="","",INDEX('Eredmény'!$AN$2:$AN$201,$W39)) | E39: =IF($W39="","",INDEX('Eredmény'!$AQ$2:$AQ$201,$W39)) | F39: =IF($W39="","",INDEX('Eredmény'!$AR$2:$AR$201,$W39)) | G39: =IF($W39="","",INDEX('Eredmény'!$AS$2:$AS$201,$W39)) | H39: =IF($W39="","",INDEX('Eredmény'!$AI$2:$AI$201,$W39)) | I39: =IF($W39="","",INDEX('Eredmény'!$AJ$2:$AJ$201,$W39)) | J39: =IF($W39="","",INDEX('Eredmény'!$AK$2:$AK$201,$W39)) | K39: =IF($W39="","",INDEX('Eredmény'!$AL$2:$AL$201,$W39)) | L39: =IF($W39="","",INDEX('Eredmény'!$AZ$2:$AZ$201,$W39)) | M39: =IF($W39="","",INDEX('Eredmény'!$BB$2:$BB$201,$W39)) | N39: =IF($W39="","",INDEX('Eredmény'!$BC$2:$BC$201,$W39)) | O39: =IF($W39="","",INDEX('Eredmény'!$BD$2:$BD$201,$W39)) | P39: =IF($W39="","",INDEX('Eredmény'!$BE$2:$BE$201,$W39)) | Q39: =IF($W39="","",INDEX('Eredmény'!$BF$2:$BF$201,$W39)) | R39: =IF($W39="","",INDEX('Eredmény'!$BG$2:$BG$201,$W39)) | S39: =IF($W39="","",INDEX('Eredmény'!$AT$2:$AT$201,$W39)) | T39: =IF($W39="","",INDEX('Eredmény'!$AV$2:$AV$201,$W39)) | U39: =IF($W39="","",INDEX('Eredmény'!$BI$2:$BI$201,$W39)) | W39: =IFERROR(MATCH(LARGE('Eredmény'!$DY$2:$DY$201,35),'Eredmény'!$DY$2:$DY$201,0),"")
A40: =IF($W40="","",INDEX('Eredmény'!$AO$2:$AO$201,$W40)) | B40: =IF($W40="","",INDEX('Eredmény'!$A$2:$A$201,$W40)) | C40: =IF($W40="","",INDEX('Eredmény'!$AM$2:$AM$201,$W40)) | D40: =IF($W40="","",INDEX('Eredmény'!$AN$2:$AN$201,$W40)) | E40: =IF($W40="","",INDEX('Eredmény'!$AQ$2:$AQ$201,$W40)) | F40: =IF($W40="","",INDEX('Eredmény'!$AR$2:$AR$201,$W40)) | G40: =IF($W40="","",INDEX('Eredmény'!$AS$2:$AS$201,$W40)) | H40: =IF($W40="","",INDEX('Eredmény'!$AI$2:$AI$201,$W40)) | I40: =IF($W40="","",INDEX('Eredmény'!$AJ$2:$AJ$201,$W40)) | J40: =IF($W40="","",INDEX('Eredmény'!$AK$2:$AK$201,$W40)) | K40: =IF($W40="","",INDEX('Eredmény'!$AL$2:$AL$201,$W40)) | L40: =IF($W40="","",INDEX('Eredmény'!$AZ$2:$AZ$201,$W40)) | M40: =IF($W40="","",INDEX('Eredmény'!$BB$2:$BB$201,$W40)) | N40: =IF($W40="","",INDEX('Eredmény'!$BC$2:$BC$201,$W40)) | O40: =IF($W40="","",INDEX('Eredmény'!$BD$2:$BD$201,$W40)) | P40: =IF($W40="","",INDEX('Eredmény'!$BE$2:$BE$201,$W40)) | Q40: =IF($W40="","",INDEX('Eredmény'!$BF$2:$BF$201,$W40)) | R40: =IF($W40="","",INDEX('Eredmény'!$BG$2:$BG$201,$W40)) | S40: =IF($W40="","",INDEX('Eredmény'!$AT$2:$AT$201,$W40)) | T40: =IF($W40="","",INDEX('Eredmény'!$AV$2:$AV$201,$W40)) | U40: =IF($W40="","",INDEX('Eredmény'!$BI$2:$BI$201,$W40)) | W40: =IFERROR(MATCH(LARGE('Eredmény'!$DY$2:$DY$201,36),'Eredmény'!$DY$2:$DY$201,0),"")
A41: =IF($W41="","",INDEX('Eredmény'!$AO$2:$AO$201,$W41)) | B41: =IF($W41="","",INDEX('Eredmény'!$A$2:$A$201,$W41)) | C41: =IF($W41="","",INDEX('Eredmény'!$AM$2:$AM$201,$W41)) | D41: =IF($W41="","",INDEX('Eredmény'!$AN$2:$AN$201,$W41)) | E41: =IF($W41="","",INDEX('Eredmény'!$AQ$2:$AQ$201,$W41)) | F41: =IF($W41="","",INDEX('Eredmény'!$AR$2:$AR$201,$W41)) | G41: =IF($W41="","",INDEX('Eredmény'!$AS$2:$AS$201,$W41)) | H41: =IF($W41="","",INDEX('Eredmény'!$AI$2:$AI$201,$W41)) | I41: =IF($W41="","",INDEX('Eredmény'!$AJ$2:$AJ$201,$W41)) | J41: =IF($W41="","",INDEX('Eredmény'!$AK$2:$AK$201,$W41)) | K41: =IF($W41="","",INDEX('Eredmény'!$AL$2:$AL$201,$W41)) | L41: =IF($W41="","",INDEX('Eredmény'!$AZ$2:$AZ$201,$W41)) | M41: =IF($W41="","",INDEX('Eredmény'!$BB$2:$BB$201,$W41)) | N41: =IF($W41="","",INDEX('Eredmény'!$BC$2:$BC$201,$W41)) | O41: =IF($W41="","",INDEX('Eredmény'!$BD$2:$BD$201,$W41)) | P41: =IF($W41="","",INDEX('Eredmény'!$BE$2:$BE$201,$W41)) | Q41: =IF($W41="","",INDEX('Eredmény'!$BF$2:$BF$201,$W41)) | R41: =IF($W41="","",INDEX('Eredmény'!$BG$2:$BG$201,$W41)) | S41: =IF($W41="","",INDEX('Eredmény'!$AT$2:$AT$201,$W41)) | T41: =IF($W41="","",INDEX('Eredmény'!$AV$2:$AV$201,$W41)) | U41: =IF($W41="","",INDEX('Eredmény'!$BI$2:$BI$201,$W41)) | W41: =IFERROR(MATCH(LARGE('Eredmény'!$DY$2:$DY$201,37),'Eredmény'!$DY$2:$DY$201,0),"")
...

Sheet Portfólió
A1: Portfólió – státuszeloszlás és célok
A2: Az arányok az elfogadott ügyfelekre vonatkoznak (az elutasított és a várólistás ügyfelek nélkül). A célok a Beállítások lapon módosíthatók.
A4: Státusz | B4: Megnevezés | C4: Ügyfelek (db) | D4: Arány
A5: 1 | B5: ='Beállítások'!$B$108 | C5: =COUNTIFS('Eredmény'!$AQ$2:$AQ$201,1,'Eredmény'!$AS$2:$AS$201,"Elfogadjuk") | D5: =IF(C11=0,"",C5/C11)
A6: 2 | B6: ='Beállítások'!$B$109 | C6: =COUNTIFS('Eredmény'!$AQ$2:$AQ$201,2,'Eredmény'!$AS$2:$AS$201,"Elfogadjuk") | D6: =IF(C11=0,"",C6/C11)
A7: 3 | B7: ='Beállítások'!$B$110 | C7: =COUNTIFS('Eredmény'!$AQ$2:$AQ$201,3,'Eredmény'!$AS$2:$AS$201,"Elfogadjuk") | D7: =IF(C11=0,"",C7/C11)
A8: 4 | B8: ='Beállítások'!$B$111 | C8: =COUNTIFS('Eredmény'!$AQ$2:$AQ$201,4,'Eredmény'!$AS$2:$AS$201,"Elfogadjuk") | D8: =IF(C11=0,"",C8/C11)
A9: 5 | B9: ='Beállítások'!$B$112 | C9: =COUNTIF('Eredmény'!$AQ$2:$AQ$201,5) | D9: elutasítva
B11: Elfogadott ügyfelek összesen | C11: =COUNTIF('Eredmény'!$AS$2:$AS$201,"Elfogadjuk")
B12: Várólistán (4-es hely foglalt) | C12: =COUNTIF('Eredmény'!$AS$2:$AS$201,"Várólista (a 4-es hely foglalt)")
B14: Ellenőrzés | C14: Cél | D14: Tény | E14: Értékelés
B15: 1–2. státusz aránya | C15: =TEXT('Beállítások'!$B$100,"0%")&"–"&TEXT('Beállítások'!$B$101,"0%") | D15: =IF(C11=0,"",(C5+C6)/C11) | E15: =IF(D15="","—",IF(D15<'Beállítások'!$B$100,"Kevesebb a célnál",IF(D15>'Beállítások'!$B$101,"Több a célnál","Rendben")))
B16: 3. státusz aránya | C16: =TEXT('Beállítások'!$B$102,"0%")&"–"&TEXT('Beállítások'!$B$103,"0%") | D16: =IF(C11=0,"",C7/C11) | E16: =IF(D16="","—",IF(D16<'Beállítások'!$B$102,"Kevesebb a célnál",IF(D16>'Beállítások'!$B$103,"Több a célnál","Rendben")))
B17: 4. státusz (db) | C17: ="legfeljebb "&'Beállítások'!$B$90 | D17: =C8 | E17: =IF(D17<='Beállítások'!$B$90,"Rendben","Túl sok")
B20: Státuszok
A21: 1 | B21: ='Beállítások'!$B$108
B22: ='Beállítások'!$G$108
A23: 2 | B23: ='Beállítások'!$B$109
B24: ='Beállítások'!$G$109
A25: 3 | B25: ='Beállítások'!$B$110
B26: ='Beállítások'!$G$110
A27: 4 | B27: ='Beállítások'!$B$111
B28: ='Beállítások'!$G$111
A29: 5 | B29: ='Beállítások'!$B$112
B30: ='Beállítások'!$G$112

Sheet Eredmény
A1: Ügyfél | B1: Értékalapú szegmens | C1: Felelősség, fenntarthatóság | D1: Sürgősség | E1: A piac mérete | F1: Árazási potenciál | G1: Vásárlószerzés költsége | H1: Leszállítás költsége | I1: Egyediség, egyedi tulajdonság | J1: A piac gyorsasága | K1: Befektetési igény | L1: Upsell-potenciál | M1: Örökzöld potenciál | N1: Látványos demonstrálhatóság | O1: Dizájn, vonzó megjelenés | P1: Egyszerű használat | Q1: Problémát old meg | R1: Újdonság | S1: Iparági illeszkedés | T1: Éves árbevétel | U1: Havi hirdetési keret | V1: Marketing-érettség | W1: Jelenlegi ROAS | X1: Növekedési potenciál | Y1: Nyitottság a jutalékos modellre | Z1: Fizetési fegyelem | AA1: Együttműködés hossza | AB1: Döntéshozó, együttműködés | AC1: Kezelhetőség | AD1: Ajánlási, referenciaérték | AE1: Reális elvárások | AF1: Emberi oldal | AG1: Szakmai színvonal | AH1: Korábbi ügynökségi tapasztalat | AI1: Értékek (0–100) | AJ1: Marketingezhetőség (0–100) | AK1: Üzleti illeszkedés (0–100) | AL1: Kapcsolat (0–100) | AM1: ICP pontszám (0–100) | AN1: Rendszerpontszám (0–100) | AO1: Rang | AP1: Kizáró feltétel | AQ1: Státusz | AR1: Státusz megnevezése | AS1: Döntés | AT1: Díjmodell | AU1: Legerősebb terület | AV1: Leggyengébb terület | AW1: Munkadíj (Ft/hó) | AX1: Státuszszorzó | AY1: Keretarányos minimum (Ft/hó) | AZ1: Javasolt fix havi díj (Ft) | BA1: Díj alapja | BB1: Jelenlegi díj (Ft) | BC1: Eltérés (Ft) | BD1: Eltérés (%) | BE1: Jutalékos modell ajánlható | BF1: Jutalékos modell: fix díj (Ft/hó) | BG1: Jutalékos modell: jutalék % | BH1: Várható jutalék (Ft/hó) | BI1: Hiányzó adatok (db) | BK1: erő: szegmens | BL1: erő: felelosseg | BM1: erő: m_surgosseg | BN1: erő: m_piacmeret | BO1: erő: m_arazas | BP1: erő: m_vevoszerzes | BQ1: erő: m_szallitas | BR1: erő: m_egyediseg | BS1: erő: m_gyorsasag | BT1: erő: m_befektetes | BU1: erő: m_upsell | BV1: erő: m_orokzold | BW1: erő: m_demonstralhato | BX1: erő: m_dizajn | BY1: erő: m_egyszeru | BZ1: erő: m_problema | CA1: erő: m_ujdonsag | CB1: erő: iparagi | CC1: erő: arbevetel | CD1: erő: keret | CE1: erő: erettseg | CF1: erő: roas | CG1: erő: novekedes | CH1: erő: jutalek_nyitottsag | CI1: erő: keses | CJ1: erő: hossz | CK1: erő: egyuttmukodes | CL1: erő: kezelhetoseg | CM1: erő: ajanlas | CN1: erő: elvarasok | CO1: erő: emberi | CP1: erő: szakmai | CQ1: erő: tapasztalat | CR1: veszt: szegmens | CS1: veszt: felelosseg | CT1: veszt: m_surgosseg | CU1: veszt: m_piacmeret | CV1: veszt: m_arazas | CW1: veszt: m_vevoszerzes | CX1: veszt: m_szallitas | CY1: veszt: m_egyediseg | CZ1: veszt: m_gyorsasag | DA1: veszt: m_befektetes | DB1: veszt: m_upsell | DC1: veszt: m_orokzold | DD1: veszt: m_demonstralhato | DE1: veszt: m_dizajn | DF1: veszt: m_egyszeru | DG1: veszt: m_problema | DH1: veszt: m_ujdonsag | DI1: veszt: iparagi | DJ1: veszt: arbevetel | DK1: veszt: keret | DL1: veszt: erettseg | DM1: veszt: roas | DN1: veszt: novekedes | DO1: veszt: jutalek_nyitottsag | DP1: veszt: keses | DQ1: veszt: hossz | DR1: veszt: egyuttmukodes | DS1: veszt: kezelhetoseg | DT1: veszt: ajanlas | DU1: veszt: elvarasok | DV1: veszt: emberi | DW1: veszt: szakmai | DX1: veszt: tapasztalat | DY1: rendezőkulcs
